xubuntu@xubuntu:~$ pip3 install --user PyQt5
Collecting PyQt5
  Using cached https://files.pythonhosted.org/packages/d4/bf/d884da8e2f7096d201c891d515eb6813a8e85df5eb6f5e12e867bf1d831c/PyQt5-5.11.3-5.11.2-cp35.cp36.cp37.cp38-abi3-manylinux1_x86_64.whl
Collecting PyQt5_sip<4.20,>=4.19.11 (from PyQt5)
  Using cached https://files.pythonhosted.org/packages/46/ba/30995383332fd46e4ee59a405bd75ae8ee099001360e7a680f1685985a49/PyQt5_sip-4.19.13-cp36-cp36m-manylinux1_x86_64.whl
Installing collected packages: PyQt5-sip, PyQt5
Exception:
Traceback (most recent call last):
  File "/usr/lib/python3/dist-packages/pip/basecommand.py", line 215, in main
    status = self.run(options, args)
  File "/usr/lib/python3/dist-packages/pip/commands/install.py", line 360, in run
    prefix=options.prefix_path,
  File "/usr/lib/python3/dist-packages/pip/req/req_set.py", line 784, in install
    **kwargs
  File "/usr/lib/python3/dist-packages/pip/req/req_install.py", line 851, in install
    self.move_wheel_files(self.source_dir, root=root, prefix=prefix)
  File "/usr/lib/python3/dist-packages/pip/req/req_install.py", line 1064, in move_wheel_files
    isolated=self.isolated,
  File "/usr/lib/python3/dist-packages/pip/wheel.py", line 506, in move_wheel_files
    installer_file.write(b'pip\n')
OSError: [Errno 28] No space left on device
xubuntu@xubuntu:~$ df
Filesystem     1K-blocks      Used Available Use% Mounted on
udev             4006800         0   4006800   0% /dev
tmpfs             805640      1364    804276   1% /run
/dev/sdb         1400768   1400768         0 100% /cdrom
/dev/loop0       1313536   1313536         0 100% /rofs
/cow             4028184   4028184         0 100% /
tmpfs            4028184         0   4028184   0% /dev/shm
tmpfs               5120         8      5112   1% /run/lock
tmpfs            4028184         0   4028184   0% /sys/fs/cgroup
tmpfs            4028184       524   4027660   1% /tmp
tmpfs             805636        20    805616   1% /run/user/999
/dev/sda2      312466428 138269052 174197376  45% /media/xubuntu/26C062DAC062AFAB
xubuntu@xubuntu:~$ sudo pip3 install --user PyQt5
The directory '/home/xubuntu/.cache/pip/http' or its parent directory is not owned by the current user and the cache has been disabled. Please check the permissions and owner of that directory. If executing pip with sudo, you may want sudo's -H flag.
The directory '/home/xubuntu/.cache/pip' or its parent directory is not owned by the current user and caching wheels has been disabled. check the permissions and owner of that directory. If executing pip with sudo, you may want sudo's -H flag.
Requirement already satisfied: PyQt5 in ./.local/lib/python3.6/site-packages
Requirement already satisfied: PyQt5_sip<4.20,>=4.19.11 in ./.local/lib/python3.6/site-packages (from PyQt5)
xubuntu@xubuntu:~$ sudo -H pip3 install --user PyQt5
Collecting PyQt5
  Retrying (Retry(total=4, connect=None, read=None, redirect=None, status=None)) after connection broken by 'NewConnectionError('<urllib3.connection.VerifiedHTTPSConnection object at 0x7f8e723b8630>: Failed to establish a new connection: [Errno 101] Network is unreachable',)': /simple/pyqt5/

